Workbook

Sheet 0. Overview
B2: Overview — Compressor Train Selection & Sizing (read-only)
B3: This sheet is protected — every cell here pulls live from the working sheets, it does not hold its own inputs. All inputs live on Sheet 1; this sheet updates automatically.
B5: 1. Process Inputs
B6: MW (lb/lbmol) | C6: ='1. Inputs'!$C$6
B7: k = Cp/Cv | C7: ='1. Inputs'!$C$7
B8: T1 (°F) | C8: ='1. Inputs'!$C$11
B9: P1 (psia) | C9: ='1. Inputs'!$C$12
B10: P2 (psia) | C10: ='1. Inputs'!$C$13
B11: mdot (lb/hr) | C11: ='1. Inputs'!$C$14
B12: N_stages (Sheets 2-5 basis) | C12: ='1. Inputs'!$C$15
B13: Per-stage pressure ratio | C13: ='1. Inputs'!$C$76
B14: Inlet flow, Q (ACFM) | C14: ='1. Inputs'!$C$78
B16: 2. Type Selection
B17: Adiabatic head, H_ad (ft) | C17: ='2. Type Selection'!C7
B18: Auto-suggested candidate(s) | C18: ='2. Type Selection'!C26
B19: Selected compressor type | C19: ='1. Inputs'!$C$30
B21: 3. Efficiency
B22: Method used | C22: ='1. Inputs'!$C$36
B23: Selected ηp | C23: ='3. Efficiency'!$C$80
B25: 4. Temp Rise & n (per stage — all stages equal)
B26: Polytropic n | C26: ='4. Temp Rise & n'!F15
B27: Discharge temp, Tout (°F) | C27: ='4. Temp Rise & n'!H15
B28: Temperature flag | C28: ='4. Temp Rise & n'!I15
B30: 5. Head & Power
B31: Per-stage gas power (hp) | C31: ='5. Head & Power'!C15
B32: Train total gas power (hp) | C32: ='5. Head & Power'!C14
B34: 6. Stage-Count Optimizer
B35: Recommended optimal N | C35: ='6. Stage Economics'!C45
B36: Suggested compressor type at that N | C36: ='6. Stage Economics'!C46
B37: TOTAL PROJECT COST at that N | C37: ='6. Stage Economics'!$C$47
B38: Sheet 1's current N_stages | C38: ='1. Inputs'!$C$15
B40: COMBINED RECOMMENDATION
C41: ='6. Stage Economics'!C51

Sheet README
B2: Compressor Train Selection & Sizing
B4: Purpose
B5: Sheets 1-5 analyze ONE stage count in full physics detail (Sheet 1's N_stages). Sheet 6 independently sweeps N=1..6, costs the equipment each implies, and recommends the largest stage count whose next stage still pays for itself — i.e. it calculates the economically optimal number of stages, it does not just screen whatever N you happened to pick. If Sheet 6's recommendation differs from Sheet 1's N_stages, update Sheet 1 to match and Sheets 2-5 re-derive automatically.
B7: Source decks
B8: Compressor Selection.pptx, Compressor Sizing.pptx, Heat Exchanger Heuristics.pptx (all in this folder), PT_payback_period_p345.pdf (Peters & Timmerhaus, Ch. 8), and ..\FEL Projects\Economics\notes\01_capital_cost_estimation.md (Guthrie/Seider module costing method reused for Sheet 6). These are the source of truth for the method used here — update this workbook if the decks change rather than hand-patching formulas.
B10: Sheet order = Sizing Workflow (Compressor Sizing.pptx, slide 4)
B11: 0. Overview | C11: Protected, read-only rollup of every sheet's key result, including the recommended optimal stage count and the total project cost at that count. Cannot be edited — change inputs on Sheet 1 instead.
B13: 1. Inputs | C13: EVERY input in the workbook: gas properties, process conditions, N_stages, economics (hours, elec. cost, mar, evaluation period), and the cost-scaling reference points for Sheet 6. Compressor type and efficiency method are auto-computed here (not manual inputs) — an "Auto" override dropdown for each lets you force a specific choice for a one-off case. Sheets 2-6 are read-only / derived from here.
B15: 2. Type Selection | C15: Computes capacity (ACFM) and adiabatic head (ft); the coverage-range table's matching row(s) are highlighted (conditional formatting) rather than plotted — a live chart was tried and dropped, since Excel has no clean way to shade a log-log rectangular region and the ScatterChart approximation proved unreliable in practice. This sheet's Q/H_ad feed Sheet 1's auto-suggestion directly — the effective type itself lives on Sheet 1, not here.
B17: 3. Efficiency | C17: Three methods per the Sizing deck: empirical correlation — three digitized curves now (Fig. 3 Reciprocating vs. pressure ratio; Fig. 1's two curves, Centrifugal and Axial, vs. suction ACFM) — Casey & Robinson scale-up (needs friction-factor data not in the deck), and Balje chart (Ns/Ds computed; chart itself is external, needs a manual ηc reading). Sheet 1 auto-picks Empirical Correlation when the (also auto) type is Reciprocating/Centrifugal/Axial, else Quick Default (rule-of-thumb) — override to Scale-Up/Balje/Manual there for a one-off case needing more precision.
B19: 4. Temp Rise & n | C19: Solves polytropic n from ηp and k, computes stage discharge temperature. Tallow is a RANGE per type (not a single cutoff) — a 3-tier flag (OK / CAUTION-inspect-specifics / EXCEEDS-add-a-stage) reflects that the true limit depends on lubricant/oil type and similar specifics outside this spreadsheet's scope.
B21: 5. Head & Power | C21: Polytropic head and gas power per stage, summed to train totals — US units only (hp); no SI kW column.
B23: 6. Stage Economics | C23: The Stage-Count Optimizer. Sweeps N=1..6 (not just Sheet 1's current N_stages) in one wide table, one row per N, with every cost constituent broken out as its own column: compressor cost via Seider Ch. 16.5 (Eq. 16.36/37/38, by consumed power, driver and material factors, CEPCI-escalated), intercooler cost via Seider's shell-and-tube equations (area from an assumed U and LMTD against a standard 90/120°F cooling-water assumption), then Guthrie bare-module + contingency + fee + working capital to the final installed cost — so it's traceable what each stage count actually costs. Compressor type is re-suggested per row, not fixed at Sheet 1's choice — adiabatic head drops non-linearly as stages are added, so a different N can land in a different Fig. 10-64 box (within one fixed N on Sheets 2-5, all stages share the same head and so the same type, since the model splits pressure ratio equally — it's only across different N here that type can genuinely change). The payback screen keeps Peters & Timmerhaus's Eq. 8-2a/8-2c structure, but its cash flow is now after-tax with straight-line depreciation added back (Seider Eq. 17.8) instead of the earlier pre-tax gross savings. Finds the largest N where every step up to it still passed that screen, subject to the Tallow temperature constraint as a hard floor, and reports the TOTAL PROJECT COST at that N. Includes a verified worked reference example as a self-check (unaffected by the cost-engine change — it exercises Eq. 8-2a/8-2c directly, not the sweep).
B26: Known gaps (not in the source decks — flagged inline, not silently guessed)
B27: • Casey & Robinson friction-factor equations 23/24 (Appendix 1 of their paper) are referenced but not included in Compressor Sizing.pptx — the scale-up method needs Bref/f values from that external source or vendor data.
B28: • The Balje chart image itself is not embedded in the deck (only the method is named) — Ns/Ds are computed here but ηc must be read off the chart elsewhere and entered manually.
B29: • Intercooler sizing here uses an assumed overall U (50 Btu/hr-ft²-F, Seider's own Ex. 16.10 precedent) and a standard 90/120°F cooling-water assumption to get an area for Seider's shell-and-tube cost equations — not a full thermal/mechanical HX design (that's still deferred per Compressor Sizing.pptx slide 10).
B30: • Seider Ch. 16.5 gives explicit compressor cost equations only for Centrifugal, Reciprocating, and Screw — Diaphragm, other Rotary sub-types, Axial, and Fan/Blower selections show 'n/a - outside Seider correlation coverage' rather than a fabricated fit; that row's TCI reads 'n/a' too.
B31: • Current CEPCI defaults to 567 (Seider's own 2013 basis, i.e. no escalation) — update it on Sheet 1 from chemengonline.com for a real, current-dollar estimate.
B32: • Combined tax rate defaults to 21% (flat federal, Texas has no state corporate income tax) — edit on Sheet 1 if a different jurisdiction or the pre-2018 graduated schedule applies.
B33: • Depreciation life for the after-tax cash flow reuses Sheet 1's N (evaluation period) rather than a separately-specified MACRS/straight-line life — a deliberate simplification since no depreciation life was specified; revisit if a real one is known.
B34: • The Stage-Count Optimizer holds ηp constant across the N=1..6 sweep (Sheet 3's value at Sheet 1's current N_stages) rather than re-deriving it per row — a documented Class-5 (±30-50%) screening simplification, not an error.
B35: • Fig. 10-64 type-selection boundaries are eyeballed from the chart image, not precisely digitized — cross-check visually (static image) for borderline operating points.

Sheet 1. Inputs
B2: 1. Process & Economic Inputs
B3: Every input in the workbook is on this sheet. Sheets 2-6 are read-only / derived — change a value here and it carries through everywhere it's used.
B5: Gas Properties
B6: Molecular weight, MW (lb/lbmol) — effective | C6: =IF($G$6="Custom / Manual Entry",$G$7,VLOOKUP($G$6,$F$11:$H$31,2,FALSE)) | D6: k is easier to compress at higher MW (fewer degrees of freedom) — Compressor Selection.pptx slide 5. | F6: Gas (choose from library at right, or "Custom / Manual Entry") | G6: Custom / Manual Entry
B7: Heat capacity ratio, k = Cp/Cv — effective | C7: =IF($G$6="Custom / Manual Entry",$G$8,VLOOKUP($G$6,$F$11:$H$31,3,FALSE)) | D7: Z is process-condition dependent (not gas-identity alone), so it stays a manual input regardless of Gas selection — see the library at right for MW/k only. | F7: Manual MW (lb/lbmol) — used only if Gas = "Custom / Manual Entry" | G7: 20
B8: Compressibility factor, Z (avg.) | C8: 1 | F8: Manual k — used only if Gas = "Custom / Manual Entry" | G8: 1.3
F9: MW/k below are approximate ideal-gas values near ambient conditions (ballpark reference only, not a flash/EOS result) — for mixtures or non-ideal conditions, use Custom / Manual Entry with your own computed values.
B10: Suction / Discharge Conditions | F10: Gas | G10: MW (lb/lbmol) | H10: k = Cp/Cv
B11: Suction temperature, T1 (°F) | C11: 100 | F11: Custom / Manual Entry
B12: Suction pressure, P1 (psia) | C12: 100 | F12: Air | G12: 28.97 | H12: 1.4
B13: Final discharge pressure, P2 (psia) | C13: 1000 | F13: Nitrogen (N2) | G13: 28.01 | H13: 1.4
B14: Mass flow rate, mdot (lb/hr) | C14: 50000 | F14: Oxygen (O2) | G14: 32 | H14: 1.395
B15: Number of stages to analyze in detail, N_stages (drives Sheets 2-5) | C15: 3 | D15: Equal pressure ratio per stage, full intercool back to T1. This is the stage count Sheets 2-5 analyze in detail — it does NOT have to equal Sheet 6's recommended optimum; update it to match once Sheet 6 tells you what that is. | F15: Hydrogen (H2) | G15: 2.016 | H15: 1.41
F16: Carbon Monoxide (CO) | G16: 28.01 | H16: 1.4
B17: Economics — General & Financial | F17: Carbon Dioxide (CO2) | G17: 44.01 | H17: 1.289
B18: Operating hours per year | C18: 8000 | F18: Methane (CH4) | G18: 16.04 | H18: 1.32
B19: Electricity cost ($/kWh) | C19: 0.07 | D19: $/kWh is the standard utility billing unit even in US-customary practice. | F19: Natural Gas (~0.60 SG) | G19: 17.4 | H19: 1.27
B20: Risk level (Table 8-1, Peters & Timmerhaus) | C20: Low - new capacity / established market | F20: Ethane (C2H6) | G20: 30.07 | H20: 1.19
B21: mar, minimum acceptable return (midpoint of risk level, editable) | C21: =AVERAGE(VLOOKUP(C20,'6. Stage Economics'!$B$18:$D$22,2,FALSE),VLOOKUP(C20,'6. Stage Economics'!$B$18:$D$22,3,FALSE)) | F21: Ethylene (C2H4) | G21: 28.05 | H21: 1.24
B22: N, evaluation period (yr) | C22: 10 | F22: Propane (C3H8) | G22: 44.1 | H22: 1.13
B23: =HYPERLINK("#'6. Stage Economics'!B16","What is mar? -> Table 8-1 guidance (Sheet 6)") | F23: Propylene (C3H6) | G23: 42.08 | H23: 1.15
F24: n-Butane (C4H10) | G24: 58.12 | H24: 1.09
B25: Compressor Type Selection — automatic | F25: Ammonia (NH3) | G25: 17.03 | H25: 1.31
B26: Compressor selection depends on adiabatic head, not manual judgment — auto-computed below from Q and H_ad at the current N_stages, using the same Fig. 10-64 box-match logic as Sheet 2 (all stages share the same head under the equal-split assumption, so one type applies to the whole train at this N — see Sheet 6 for how type CAN genuinely differ across different N choices, since head there varies a lot more). | F26: Hydrogen Sulfide (H2S) | G26: 34.08 | H26: 1.32
F27: Chlorine (Cl2) | G27: 70.9 | H27: 1.34
B28: Auto-suggested compressor type (from adiabatic head — patched in once Sheet 2 exists) | C28: =IF(LEN(J28)=0,"None",LEFT(J28,SEARCH(", ",J28)-1)) | F28: Sulfur Dioxide (SO2) | G28: 64.07 | H28: 1.29 | J28: =IF(AND('2. Type Selection'!$C$6>='2. Type Selection'!C14,'2. Type Selection'!$C$6<='2. Type Selection'!D14,'2. Type Selection'!$C$7>='2. Type Selection'!E14,'2. Type Selection'!$C$7<='2. Type Selection'!F14),'2. Type Selection'!B14&", ","")&IF(AND('2. Type Selection'!$C$6>='2. Type Selection'!C15,'2. Type Selection'!$C$6<='2. Type Selection'!D15,'2. Type Selection'!$C$7>='2. Type Selection'!E15,'2. Type Selection'!$C$7<='2. Type Selection'!F15),'2. Type Selection'!B15&", ","")&IF(AND('2. Type Selection'!$C$6>='2. Type Selection'!C16,'2. Type Selection'!$C$6<='2. Type Selection'!D16,'2. Type Selection'!$C$7>='2. Type Selection'!E16,'2. Type Selection'!$C$7<='2. Type Selection'!F16),'2. Type Selection'!B16&", ","")&IF(AND('2. Type Selection'!$C$6>='2. Type Selection'!C17,'2. Type Selection'!$C$6<='2. Type Selection'!D17,'2. Type Selection'!$C$7>='2. Type Selection'!E17,'2. Type Selection'!$C$7<='2. Type Selection'!F17),'2. Type Selection'!B17&", ","")&IF(AND('2. Type Selection'!$C$6>='2. Type Selection'!C18,'2. Type Selection'!$C$6<='2. Type Selection'!D18,'2. Type Selection'!$C$7>='2. Type Selection'!E18,'2. Type Selection'!$C$7<='2. Type Selection'!F18),'2. Type Selection'!B18&", ","")&IF(AND('2. Type Selection'!$C$6>='2. Type Selection'!C19,'2. Type Selection'!$C$6<='2. Type Selection'!D19,'2. Type Selection'!$C$7>='2. Type Selection'!E19,'2. Type Selection'!$C$7<='2. Type Selection'!F19),'2. Type Selection'!B19&", ","")&IF(AND('2. Type Selection'!$C$6>='2. Type Selection'!C20,'2. Type Selection'!$C$6<='2. Type Selection'!D20,'2. Type Selection'!$C$7>='2. Type Selection'!E20,'2. Type Selection'!$C$7<='2. Type Selection'!F20),'2. Type Selection'!B20&", ","")&IF(AND('2. Type Selection'!$C$6>='2. Type Selection'!C21,'2. Type Selection'!$C$6<='2. Type Selection'!D21,'2. Type Selection'!$C$7>='2. Type Selection'!E21,'2. Type Selection'!$C$7<='2. Type Selection'!F21),'2. Type Selection'!B21&", ","")&IF(AND('2. Type Selection'!$C$6>='2. Type Selection'!C22,'2. Type Selection'!$C$6<='2. Type Selection'!D22,'2. Type Selection'!$C$7>='2. Type Selection'!E22,'2. Type Selection'!$C$7<='2. Type Selection'!F22),'2. Type Selection'!B22&", ","")&IF(AND('2. Type Selection'!$C$6>='2. Type Selection'!C23,'2. Type Selection'!$C$6<='2. Type Selection'!D23,'2. Type Selection'!$C$7>='2. Type Selection'!E23,'2. Type Selection'!$C$7<='2. Type Selection'!F23),'2. Type Selection'!B23&", ","")
B29: Manual override (pick a type for a one-off case, or leave "Auto") | C29: Auto | F29: Water Vapor / Steam (H2O) | G29: 18.02 | H29: 1.33
B30: Effective selected type (used everywhere) | C30: =IF(C29="Auto",C28,C29) | F30: Argon (Ar) | G30: 39.95 | H30: 1.667
F31: Helium (He) | G31: 4.003 | H31: 1.667
B32: Efficiency Method — auto-selected by type
B33: Reciprocating, Centrifugal, and Axial each have a real digitized correlation chart in the source deck (Fig. 3 and Fig. 1) — every other type (Rotary sub-types, Diaphragm, Fan/Blower) auto-falls-back to the rule-of-thumb Quick Default. Override to Scale-Up, Balje, or Manual below for a one-off case that needs more precision than either gives; see Sheet 3 for what data each of those needs.
B35: Method override (pick one, or leave "Auto" for the type-based default) | C35: Auto
B36: Effective method (used everywhere) | C36: =IF(C35<>"Auto",C35,IF(OR(ISNUMBER(SEARCH("Reciprocating",C30)),ISNUMBER(SEARCH("Centrifugal",C30)),ISNUMBER(SEARCH("Axial",C30))),"Empirical Correlation","Quick Default"))
B38: Manual ηp (used only if Method = Manual) | C38: 0.75
B40: Scale-Up method inputs (Casey & Robinson Eq. 17 — needs external friction-factor data, see Sheet 3)
B41: η1 (reference efficiency) | C41: 0
B42: Bref | C42: 0
B43: fref | C43: 0
B44: f1 | C44: 0
B45: f2 | C45: 0
...

Sheet 2. Type Selection
B2: 2. Compressor Type Selection
B3: "Compressor selection is primarily based on capacity and head requirements" — Compressor Selection.pptx slide 7. Boundaries below are approximate, eyeballed from the embedded Fig. 10-64 coverage chart. Change the selected type on Sheet 1, not here.
B5: Computed Operating Point
B6: Capacity, Q (ACFM at suction) | C6: ='1. Inputs'!$C$78
B7: Adiabatic head, H_ad (ft) [n=k, per stage] | C7: =('1. Inputs'!$C$7/('1. Inputs'!$C$7-1))*'1. Inputs'!$C$74*'1. Inputs'!$C$73*('1. Inputs'!$C$76^(('1. Inputs'!$C$7-1)/'1. Inputs'!$C$7)-1)
B8: Effective compressor type (auto-computed on Sheet 1 from Q/H_ad above; override available there) | C8: ='1. Inputs'!$C$30
B10: Approx. Coverage Ranges (digitized from Fig. 10-64) — the highlighted row(s) contain your current operating point
B11: A live chart was tried here and dropped — Excel's charting has no clean way to shade a log-log rectangular region, and a ScatterChart approximation proved unreliable in practice. Row highlighting (conditional formatting, driven by the same Q/H comparison) is simpler and equally informative.
B13: Type | C13: Q_min (ACFM) | D13: Q_max (ACFM) | E13: H_min (ft) | F13: H_max (ft)
B14: Diaphragm | C14: 1 | D14: 10 | E14: 1000 | F14: 100000
B15: Reciprocating | C15: 1 | D15: 3000 | E15: 500 | F15: 100000
B16: Rotary - Straight Lobe | C16: 100 | D16: 3000 | E16: 100 | F16: 1000
B17: Rotary - Screw | C17: 10 | D17: 3000 | E17: 100 | F17: 10000
B18: Rotary - Sliding Vane | C18: 10 | D18: 1000 | E18: 100 | F18: 3000
B19: Rotary - Liquid Piston | C19: 1 | D19: 300 | E19: 1000 | F19: 10000
B20: Centrifugal - Single Stage | C20: 1000 | D20: 100000 | E20: 100 | F20: 10000
B21: Centrifugal - Multistage | C21: 500 | D21: 100000 | E21: 1000 | F21: 100000
B22: Axial - Multistage | C22: 3000 | D22: 100000 | E22: 100 | F22: 3000
B23: Fan / Blower | C23: 1000 | D23: 100000 | E23: 10 | F23: 1000
B25: Auto-Suggestion (candidates whose box contains the operating point)
B26: Candidate type(s) | C26: =IF(LEN(H26)=0,"(no boundary match - inspect Fig. 10-64 chart manually)",LEFT(H26,LEN(H26)-2)) | H26: =IF(AND($C$6>=C14,$C$6<=D14,$C$7>=E14,$C$7<=F14),B14&", ","")&IF(AND($C$6>=C15,$C$6<=D15,$C$7>=E15,$C$7<=F15),B15&", ","")&IF(AND($C$6>=C16,$C$6<=D16,$C$7>=E16,$C$7<=F16),B16&", ","")&IF(AND($C$6>=C17,$C$6<=D17,$C$7>=E17,$C$7<=F17),B17&", ","")&IF(AND($C$6>=C18,$C$6<=D18,$C$7>=E18,$C$7<=F18),B18&", ","")&IF(AND($C$6>=C19,$C$6<=D19,$C$7>=E19,$C$7<=F19),B19&", ","")&IF(AND($C$6>=C20,$C$6<=D20,$C$7>=E20,$C$7<=F20),B20&", ","")&IF(AND($C$6>=C21,$C$6<=D21,$C$7>=E21,$C$7<=F21),B21&", ","")&IF(AND($C$6>=C22,$C$6<=D22,$C$7>=E22,$C$7<=F22),B22&", ","")&IF(AND($C$6>=C23,$C$6<=D23,$C$7>=E23,$C$7<=F23),B23&", ","")
B28: Additional selection parameters mentioned in the deck (Reynolds number, specific speed Ns, specific diameter Ds, flow coefficient φ, pressure coefficient Ψ) are standard turbomachinery similarity parameters used mainly to refine centrifugal-stage/impeller choice once a vendor curve is available — not computed here since the deck names them without giving the specific formulas used.
B31: Qualitative Notes by Type (from Compressor Selection.pptx)
B32: Centrifugal [Continuous, Dynamic] | C32: Multiple stages for lower power input; backward-curved blades most common; surges at min flow, chokes at max flow.
B34: Reciprocating [Positive Displacement] | C34: High pressure ratio, low flow; discharge temperature limits pressure ratio (lubricant degradation, thermal expansion); multi-stage needs interstage coolers; ~80% efficient; rod-packing failure is an overpressure scenario — PSV required on vent piping.
B36: Rotary [Positive Displacement] | C36: Straight lobe, screw, sliding vane, or liquid piston sub-types.
B38: Axial [Continuous, Dynamic] | C38: Low head, high flow, small operating range; used for gas turbines/aircraft.
B40: Fans / Blowers | C40: Fans <0.5 psi, blowers <1.5 psi delivery; axial fans for high flow/low pressure; centrifugal blowers most common, no cooling required (ratio ~3.5).
B42: Ejectors [Continuous] | C42: Steam-driven vacuum alternative to a compressor; low maintenance/cost, environmental tradeoff; not sized on this sheet.
B45: Fig. 10-64 — Compressor coverage chart (Perry's, via Compressor Selection.pptx), for visual cross-check against the live plot above

Sheet 3. Efficiency
B2: 3. Polytropic Efficiency Estimation
B3: Three methods from Compressor Sizing.pptx slide 4-7. The method choice and all manual inputs (Scale-Up, Balje, Manual ηp) are set on Sheet 1 — this sheet shows the resulting computation for each.
B5: Method 1: Empirical Correlation — three digitized curves by type
B6: ηp increases with flow rate and pressure ratio; general range 70-80% (Compressor Sizing.pptx slide 5). Reciprocating uses Fig. 3 (vs. pressure ratio); Centrifugal and Axial use the two curves on Fig. 1 (vs. suction ACFM) — added when the deck was updated with that chart. Any other type still has no digitized chart and falls back to Quick Defaults below.
B8: Reciprocating (Fig. 3, vs. pressure ratio)
B9: Pressure ratio | C9: ηp
B10: 1.5 | C10: 0.74
B11: 2 | C11: 0.79
B12: 2.5 | C12: 0.815
B13: 3 | C13: 0.825
B14: 3.5 | C14: 0.833
B15: 4 | C15: 0.84
B16: 4.5 | C16: 0.843
B17: 5 | C17: 0.846
B18: 5.5 | C18: 0.848
B19: 6 | C19: 0.846
B20: 6.5 | C20: 0.843
B21: Interpolated ηp (Reciprocating) | C21: =IF('1. Inputs'!$C$76<=B10,C10,IF('1. Inputs'!$C$76>=B20,C20,INDEX($C$10:$C$20,MATCH('1. Inputs'!$C$76,$B$10:$B$20,1))+(INDEX($C$10:$C$20,MATCH('1. Inputs'!$C$76,$B$10:$B$20,1)+1)-INDEX($C$10:$C$20,MATCH('1. Inputs'!$C$76,$B$10:$B$20,1)))*('1. Inputs'!$C$76-INDEX($B$10:$B$20,MATCH('1. Inputs'!$C$76,$B$10:$B$20,1)))/(INDEX($B$10:$B$20,MATCH('1. Inputs'!$C$76,$B$10:$B$20,1)+1)-INDEX($B$10:$B$20,MATCH('1. Inputs'!$C$76,$B$10:$B$20,1)))))
B23: Centrifugal (Fig. 1, vs. suction ACFM)
B24: Suction ACFM | C24: ηp
B25: 1000 | C25: 0.65
B26: 2000 | C26: 0.7
B27: 4000 | C27: 0.72
B28: 7000 | C28: 0.73
B29: 10000 | C29: 0.735
B30: 20000 | C30: 0.745
B31: 40000 | C31: 0.755
B32: 70000 | C32: 0.763
B33: 100000 | C33: 0.766
B34: 200000 | C34: 0.77
B35: Interpolated ηp (Centrifugal) | C35: =IF('1. Inputs'!$C$78<=B25,C25,IF('1. Inputs'!$C$78>=B34,C34,INDEX($C$25:$C$34,MATCH('1. Inputs'!$C$78,$B$25:$B$34,1))+(INDEX($C$25:$C$34,MATCH('1. Inputs'!$C$78,$B$25:$B$34,1)+1)-INDEX($C$25:$C$34,MATCH('1. Inputs'!$C$78,$B$25:$B$34,1)))*('1. Inputs'!$C$78-INDEX($B$25:$B$34,MATCH('1. Inputs'!$C$78,$B$25:$B$34,1)))/(INDEX($B$25:$B$34,MATCH('1. Inputs'!$C$78,$B$25:$B$34,1)+1)-INDEX($B$25:$B$34,MATCH('1. Inputs'!$C$78,$B$25:$B$34,1)))))
B37: Axial (Fig. 1, vs. suction ACFM)
B38: Suction ACFM | C38: ηp
B39: 75000 | C39: 0.813
B40: 100000 | C40: 0.817
B41: 200000 | C41: 0.827
B42: 400000 | C42: 0.832
B43: 600000 | C43: 0.836
B44: Interpolated ηp (Axial) | C44: =IF('1. Inputs'!$C$78<=B39,C39,IF('1. Inputs'!$C$78>=B43,C43,INDEX($C$39:$C$43,MATCH('1. Inputs'!$C$78,$B$39:$B$43,1))+(INDEX($C$39:$C$43,MATCH('1. Inputs'!$C$78,$B$39:$B$43,1)+1)-INDEX($C$39:$C$43,MATCH('1. Inputs'!$C$78,$B$39:$B$43,1)))*('1. Inputs'!$C$78-INDEX($B$39:$B$43,MATCH('1. Inputs'!$C$78,$B$39:$B$43,1)))/(INDEX($B$39:$B$43,MATCH('1. Inputs'!$C$78,$B$39:$B$43,1)+1)-INDEX($B$39:$B$43,MATCH('1. Inputs'!$C$78,$B$39:$B$43,1)))))
B46: Empirical Correlation result (routes by effective type) | C46: =IF(ISNUMBER(SEARCH("Reciprocating",'1. Inputs'!$C$30)),C21,IF(ISNUMBER(SEARCH("Centrifugal",'1. Inputs'!$C$30)),C35,IF(ISNUMBER(SEARCH("Axial",'1. Inputs'!$C$30)),C44,"n/a - no digitized chart for this type, use Quick Default")))
...

Sheet 4. Temp Rise & n
B2: 4. Polytropic Coefficient n and Discharge Temperature per Stage
B3: ηp = [n/(n-1)] / [k/(k-1)] (Compressor Selection.pptx slide 6) solved for n. Discharge temp Tout = T1·r_stage^((n-1)/n), assuming each stage's suction is intercooled back to T1. Compare against Tallow (Compressor Sizing.pptx slide 8, Table below).
B5: Max Allowable Discharge Temperature, Tallow (°F) — RANGES, not single limits
B6: Type | C6: Min (°F) | D6: Max (°F) | E6: Notes
B7: Reciprocating | C7: 300 | D7: 350 | E7: Flammable gases (e.g. H2) push the effective limit toward 300F
B8: Centrifugal | C8: 392 | D8: 446 | E8: API 617 + industry practice
B9: Rotary | C9: 212 | D9: 350 | E9: Heavily dependent on oil type — some oils degrade at temperatures as low as 212F
B11: The range reflects real variability by construction/lubricant, not measurement uncertainty. Tout between Min and Max does not mean "safe" — it means the specific vendor/oil/seal rating must be checked; this spreadsheet flags it rather than silently picking an endpoint.
B13: Per-Stage Calculation (up to 6 stages; blank rows beyond N_stages)
B14: Stage | C14: Suction P (psia) | D14: Discharge P (psia) | E14: T1 (°R) | F14: n | G14: Tout (°R) | H14: Tout (°F) | I14: vs. Tallow
B15: 1 | C15: =IF(B15<='1. Inputs'!$C$15,'1. Inputs'!$C$12*'1. Inputs'!$C$76^(B15-1),"") | D15: =IF(B15<='1. Inputs'!$C$15,'1. Inputs'!$C$12*'1. Inputs'!$C$76^B15,"") | E15: =IF(B15<='1. Inputs'!$C$15,'1. Inputs'!$C$73,"") | F15: =IF(B15<='1. Inputs'!$C$15,1/(1-(('1. Inputs'!$C$7-1)/('1. Inputs'!$C$7*'3. Efficiency'!$C$80))),"") | G15: =IF(B15<='1. Inputs'!$C$15,E15*'1. Inputs'!$C$76^((F15-1)/F15),"") | H15: =IF(B15<='1. Inputs'!$C$15,G15-459.67,"") | I15: =IF(B15>'1. Inputs'!$C$15,"",IF('1. Inputs'!$C$30="None","UNKNOWN TYPE - no compressor in the coverage table fits these conditions; cannot verify Tallow, treated as EXCEEDS until inspected manually",IF(ISNUMBER(SEARCH("Reciprocating",'1. Inputs'!$C$30)),IF(H15>350,"EXCEEDS 350F - add a stage",IF(H15>300,"CAUTION: 300-350F is vendor/lubricant dependent - inspect the specific compressor rating (outside scope of this spreadsheet)","OK")),IF(ISNUMBER(SEARCH("Centrifugal",'1. Inputs'!$C$30)),IF(H15>446,"EXCEEDS 446F - add a stage",IF(H15>392,"CAUTION: 392-446F is vendor/lubricant dependent - inspect the specific compressor rating (outside scope of this spreadsheet)","OK")),IF(ISNUMBER(SEARCH("Rotary",'1. Inputs'!$C$30)),IF(H15>350,"EXCEEDS 350F - add a stage",IF(H15>212,"CAUTION: 212-350F is vendor/lubricant dependent - inspect the specific compressor rating (outside scope of this spreadsheet)","OK")),"n/a (Axial/Fan - no Tallow range given in the deck)")))))
B16: 2 | C16: =IF(B16<='1. Inputs'!$C$15,'1. Inputs'!$C$12*'1. Inputs'!$C$76^(B16-1),"") | D16: =IF(B16<='1. Inputs'!$C$15,'1. Inputs'!$C$12*'1. Inputs'!$C$76^B16,"") | E16: =IF(B16<='1. Inputs'!$C$15,'1. Inputs'!$C$73,"") | F16: =IF(B16<='1. Inputs'!$C$15,1/(1-(('1. Inputs'!$C$7-1)/('1. Inputs'!$C$7*'3. Efficiency'!$C$80))),"") | G16: =IF(B16<='1. Inputs'!$C$15,E16*'1. Inputs'!$C$76^((F16-1)/F16),"") | H16: =IF(B16<='1. Inputs'!$C$15,G16-459.67,"") | I16: =IF(B16>'1. Inputs'!$C$15,"",IF('1. Inputs'!$C$30="None","UNKNOWN TYPE - no compressor in the coverage table fits these conditions; cannot verify Tallow, treated as EXCEEDS until inspected manually",IF(ISNUMBER(SEARCH("Reciprocating",'1. Inputs'!$C$30)),IF(H16>350,"EXCEEDS 350F - add a stage",IF(H16>300,"CAUTION: 300-350F is vendor/lubricant dependent - inspect the specific compressor rating (outside scope of this spreadsheet)","OK")),IF(ISNUMBER(SEARCH("Centrifugal",'1. Inputs'!$C$30)),IF(H16>446,"EXCEEDS 446F - add a stage",IF(H16>392,"CAUTION: 392-446F is vendor/lubricant dependent - inspect the specific compressor rating (outside scope of this spreadsheet)","OK")),IF(ISNUMBER(SEARCH("Rotary",'1. Inputs'!$C$30)),IF(H16>350,"EXCEEDS 350F - add a stage",IF(H16>212,"CAUTION: 212-350F is vendor/lubricant dependent - inspect the specific compressor rating (outside scope of this spreadsheet)","OK")),"n/a (Axial/Fan - no Tallow range given in the deck)")))))
B17: 3 | C17: =IF(B17<='1. Inputs'!$C$15,'1. Inputs'!$C$12*'1. Inputs'!$C$76^(B17-1),"") | D17: =IF(B17<='1. Inputs'!$C$15,'1. Inputs'!$C$12*'1. Inputs'!$C$76^B17,"") | E17: =IF(B17<='1. Inputs'!$C$15,'1. Inputs'!$C$73,"") | F17: =IF(B17<='1. Inputs'!$C$15,1/(1-(('1. Inputs'!$C$7-1)/('1. Inputs'!$C$7*'3. Efficiency'!$C$80))),"") | G17: =IF(B17<='1. Inputs'!$C$15,E17*'1. Inputs'!$C$76^((F17-1)/F17),"") | H17: =IF(B17<='1. Inputs'!$C$15,G17-459.67,"") | I17: =IF(B17>'1. Inputs'!$C$15,"",IF('1. Inputs'!$C$30="None","UNKNOWN TYPE - no compressor in the coverage table fits these conditions; cannot verify Tallow, treated as EXCEEDS until inspected manually",IF(ISNUMBER(SEARCH("Reciprocating",'1. Inputs'!$C$30)),IF(H17>350,"EXCEEDS 350F - add a stage",IF(H17>300,"CAUTION: 300-350F is vendor/lubricant dependent - inspect the specific compressor rating (outside scope of this spreadsheet)","OK")),IF(ISNUMBER(SEARCH("Centrifugal",'1. Inputs'!$C$30)),IF(H17>446,"EXCEEDS 446F - add a stage",IF(H17>392,"CAUTION: 392-446F is vendor/lubricant dependent - inspect the specific compressor rating (outside scope of this spreadsheet)","OK")),IF(ISNUMBER(SEARCH("Rotary",'1. Inputs'!$C$30)),IF(H17>350,"EXCEEDS 350F - add a stage",IF(H17>212,"CAUTION: 212-350F is vendor/lubricant dependent - inspect the specific compressor rating (outside scope of this spreadsheet)","OK")),"n/a (Axial/Fan - no Tallow range given in the deck)")))))
B18: 4 | C18: =IF(B18<='1. Inputs'!$C$15,'1. Inputs'!$C$12*'1. Inputs'!$C$76^(B18-1),"") | D18: =IF(B18<='1. Inputs'!$C$15,'1. Inputs'!$C$12*'1. Inputs'!$C$76^B18,"") | E18: =IF(B18<='1. Inputs'!$C$15,'1. Inputs'!$C$73,"") | F18: =IF(B18<='1. Inputs'!$C$15,1/(1-(('1. Inputs'!$C$7-1)/('1. Inputs'!$C$7*'3. Efficiency'!$C$80))),"") | G18: =IF(B18<='1. Inputs'!$C$15,E18*'1. Inputs'!$C$76^((F18-1)/F18),"") | H18: =IF(B18<='1. Inputs'!$C$15,G18-459.67,"") | I18: =IF(B18>'1. Inputs'!$C$15,"",IF('1. Inputs'!$C$30="None","UNKNOWN TYPE - no compressor in the coverage table fits these conditions; cannot verify Tallow, treated as EXCEEDS until inspected manually",IF(ISNUMBER(SEARCH("Reciprocating",'1. Inputs'!$C$30)),IF(H18>350,"EXCEEDS 350F - add a stage",IF(H18>300,"CAUTION: 300-350F is vendor/lubricant dependent - inspect the specific compressor rating (outside scope of this spreadsheet)","OK")),IF(ISNUMBER(SEARCH("Centrifugal",'1. Inputs'!$C$30)),IF(H18>446,"EXCEEDS 446F - add a stage",IF(H18>392,"CAUTION: 392-446F is vendor/lubricant dependent - inspect the specific compressor rating (outside scope of this spreadsheet)","OK")),IF(ISNUMBER(SEARCH("Rotary",'1. Inputs'!$C$30)),IF(H18>350,"EXCEEDS 350F - add a stage",IF(H18>212,"CAUTION: 212-350F is vendor/lubricant dependent - inspect the specific compressor rating (outside scope of this spreadsheet)","OK")),"n/a (Axial/Fan - no Tallow range given in the deck)")))))
B19: 5 | C19: =IF(B19<='1. Inputs'!$C$15,'1. Inputs'!$C$12*'1. Inputs'!$C$76^(B19-1),"") | D19: =IF(B19<='1. Inputs'!$C$15,'1. Inputs'!$C$12*'1. Inputs'!$C$76^B19,"") | E19: =IF(B19<='1. Inputs'!$C$15,'1. Inputs'!$C$73,"") | F19: =IF(B19<='1. Inputs'!$C$15,1/(1-(('1. Inputs'!$C$7-1)/('1. Inputs'!$C$7*'3. Efficiency'!$C$80))),"") | G19: =IF(B19<='1. Inputs'!$C$15,E19*'1. Inputs'!$C$76^((F19-1)/F19),"") | H19: =IF(B19<='1. Inputs'!$C$15,G19-459.67,"") | I19: =IF(B19>'1. Inputs'!$C$15,"",IF('1. Inputs'!$C$30="None","UNKNOWN TYPE - no compressor in the coverage table fits these conditions; cannot verify Tallow, treated as EXCEEDS until inspected manually",IF(ISNUMBER(SEARCH("Reciprocating",'1. Inputs'!$C$30)),IF(H19>350,"EXCEEDS 350F - add a stage",IF(H19>300,"CAUTION: 300-350F is vendor/lubricant dependent - inspect the specific compressor rating (outside scope of this spreadsheet)","OK")),IF(ISNUMBER(SEARCH("Centrifugal",'1. Inputs'!$C$30)),IF(H19>446,"EXCEEDS 446F - add a stage",IF(H19>392,"CAUTION: 392-446F is vendor/lubricant dependent - inspect the specific compressor rating (outside scope of this spreadsheet)","OK")),IF(ISNUMBER(SEARCH("Rotary",'1. Inputs'!$C$30)),IF(H19>350,"EXCEEDS 350F - add a stage",IF(H19>212,"CAUTION: 212-350F is vendor/lubricant dependent - inspect the specific compressor rating (outside scope of this spreadsheet)","OK")),"n/a (Axial/Fan - no Tallow range given in the deck)")))))
B20: 6 | C20: =IF(B20<='1. Inputs'!$C$15,'1. Inputs'!$C$12*'1. Inputs'!$C$76^(B20-1),"") | D20: =IF(B20<='1. Inputs'!$C$15,'1. Inputs'!$C$12*'1. Inputs'!$C$76^B20,"") | E20: =IF(B20<='1. Inputs'!$C$15,'1. Inputs'!$C$73,"") | F20: =IF(B20<='1. Inputs'!$C$15,1/(1-(('1. Inputs'!$C$7-1)/('1. Inputs'!$C$7*'3. Efficiency'!$C$80))),"") | G20: =IF(B20<='1. Inputs'!$C$15,E20*'1. Inputs'!$C$76^((F20-1)/F20),"") | H20: =IF(B20<='1. Inputs'!$C$15,G20-459.67,"") | I20: =IF(B20>'1. Inputs'!$C$15,"",IF('1. Inputs'!$C$30="None","UNKNOWN TYPE - no compressor in the coverage table fits these conditions; cannot verify Tallow, treated as EXCEEDS until inspected manually",IF(ISNUMBER(SEARCH("Reciprocating",'1. Inputs'!$C$30)),IF(H20>350,"EXCEEDS 350F - add a stage",IF(H20>300,"CAUTION: 300-350F is vendor/lubricant dependent - inspect the specific compressor rating (outside scope of this spreadsheet)","OK")),IF(ISNUMBER(SEARCH("Centrifugal",'1. Inputs'!$C$30)),IF(H20>446,"EXCEEDS 446F - add a stage",IF(H20>392,"CAUTION: 392-446F is vendor/lubricant dependent - inspect the specific compressor rating (outside scope of this spreadsheet)","OK")),IF(ISNUMBER(SEARCH("Rotary",'1. Inputs'!$C$30)),IF(H20>350,"EXCEEDS 350F - add a stage",IF(H20>212,"CAUTION: 212-350F is vendor/lubricant dependent - inspect the specific compressor rating (outside scope of this spreadsheet)","OK")),"n/a (Axial/Fan - no Tallow range given in the deck)")))))
E23: n=1 isothermal, n=k adiabatic, n>k polytropic — higher n gives greater temperature rise (Compressor Selection.pptx slide 5).

Sheet 5. Head & Power
B2: 5. Polytropic Head and Power per Stage
B3: Hp = [n/(n-1)]·Z·R'·T1·[(P2/P1)^((n-1)/n) - 1] (ft·lbf/lbm ≡ ft of gas). Pgas = mdot·Hp/ηp (Compressor Selection.pptx slide 6). All US units — hp only, no kW column.
B5: Stage | C5: Hp (ft) | D5: ηp | E5: Pgas (ft·lbf/hr) | F5: Pgas (hp)
B6: 1 | C6: =IF(B6>'1. Inputs'!$C$15,"",(('4. Temp Rise & n'!F15)/('4. Temp Rise & n'!F15-1))*'1. Inputs'!$C$8*'1. Inputs'!$C$74*'4. Temp Rise & n'!E15*('1. Inputs'!$C$76^(('4. Temp Rise & n'!F15-1)/'4. Temp Rise & n'!F15)-1)) | D6: ='3. Efficiency'!$C$80 | E6: =IF(B6>'1. Inputs'!$C$15,"",'1. Inputs'!$C$14*C6/D6) | F6: =IF(B6>'1. Inputs'!$C$15,"",E6/1980000)
B7: 2 | C7: =IF(B7>'1. Inputs'!$C$15,"",(('4. Temp Rise & n'!F16)/('4. Temp Rise & n'!F16-1))*'1. Inputs'!$C$8*'1. Inputs'!$C$74*'4. Temp Rise & n'!E16*('1. Inputs'!$C$76^(('4. Temp Rise & n'!F16-1)/'4. Temp Rise & n'!F16)-1)) | D7: ='3. Efficiency'!$C$80 | E7: =IF(B7>'1. Inputs'!$C$15,"",'1. Inputs'!$C$14*C7/D7) | F7: =IF(B7>'1. Inputs'!$C$15,"",E7/1980000)
B8: 3 | C8: =IF(B8>'1. Inputs'!$C$15,"",(('4. Temp Rise & n'!F17)/('4. Temp Rise & n'!F17-1))*'1. Inputs'!$C$8*'1. Inputs'!$C$74*'4. Temp Rise & n'!E17*('1. Inputs'!$C$76^(('4. Temp Rise & n'!F17-1)/'4. Temp Rise & n'!F17)-1)) | D8: ='3. Efficiency'!$C$80 | E8: =IF(B8>'1. Inputs'!$C$15,"",'1. Inputs'!$C$14*C8/D8) | F8: =IF(B8>'1. Inputs'!$C$15,"",E8/1980000)
B9: 4 | C9: =IF(B9>'1. Inputs'!$C$15,"",(('4. Temp Rise & n'!F18)/('4. Temp Rise & n'!F18-1))*'1. Inputs'!$C$8*'1. Inputs'!$C$74*'4. Temp Rise & n'!E18*('1. Inputs'!$C$76^(('4. Temp Rise & n'!F18-1)/'4. Temp Rise & n'!F18)-1)) | D9: ='3. Efficiency'!$C$80 | E9: =IF(B9>'1. Inputs'!$C$15,"",'1. Inputs'!$C$14*C9/D9) | F9: =IF(B9>'1. Inputs'!$C$15,"",E9/1980000)
B10: 5 | C10: =IF(B10>'1. Inputs'!$C$15,"",(('4. Temp Rise & n'!F19)/('4. Temp Rise & n'!F19-1))*'1. Inputs'!$C$8*'1. Inputs'!$C$74*'4. Temp Rise & n'!E19*('1. Inputs'!$C$76^(('4. Temp Rise & n'!F19-1)/'4. Temp Rise & n'!F19)-1)) | D10: ='3. Efficiency'!$C$80 | E10: =IF(B10>'1. Inputs'!$C$15,"",'1. Inputs'!$C$14*C10/D10) | F10: =IF(B10>'1. Inputs'!$C$15,"",E10/1980000)
B11: 6 | C11: =IF(B11>'1. Inputs'!$C$15,"",(('4. Temp Rise & n'!F20)/('4. Temp Rise & n'!F20-1))*'1. Inputs'!$C$8*'1. Inputs'!$C$74*'4. Temp Rise & n'!E20*('1. Inputs'!$C$76^(('4. Temp Rise & n'!F20-1)/'4. Temp Rise & n'!F20)-1)) | D11: ='3. Efficiency'!$C$80 | E11: =IF(B11>'1. Inputs'!$C$15,"",'1. Inputs'!$C$14*C11/D11) | F11: =IF(B11>'1. Inputs'!$C$15,"",E11/1980000)
B13: Train Totals (at Sheet 1's N_stages)
B14: Total gas power, sum(Pgas) | C14: =SUM(F6:F11) | D14: hp
B15: Per-stage gas power (all stages equal under the equal-split / full-intercool assumption) | C15: =F6 | D15: hp/stage

Sheet 6. Stage Economics
B2: 6. Stage-Count Optimizer — How Many Stages Should There Be?
B3: This sheet answers a DIFFERENT question than Sheets 2-5: not "is my chosen N_stages OK" but "what is the economically optimal N, from 1 to 6". It sweeps every stage count, costs the compressor + intercoolers actually implied at each one, and finds the largest N whose next stage still pays for itself — subject to the Tallow temperature constraint always winning if it's violated. Compressor Sizing.pptx slide 4's "back to step 1 with 1 additional stage" loop is what this sweep automates.
B4: Simplification: ηp is held constant across the sweep at Sheet 3's Selected ηp (computed at Sheet 1's current N_stages) — re-deriving ηp per row would need the full method-selection logic duplicated 6 times. Acceptable at this Class-5 (±30-50%) estimate accuracy; ηp does shift slightly with pressure ratio in reality.
B6: Reference Example (from the annotated PBP PDF — self-check only, do not edit)
B7: ΔTCI: compressor stage (BMF 2.15) + intercooler HX (BMF 3.29), built up through contingency/fee/working capital | C7: 631880
B8: ΔCOM: annual power-savings cash flow | C8: 129163
B9: mar (Low-Medium risk, Table 8-1) | C9: 0.12
B10: N, evaluation period (yr) | C10: 15
B11: PBP = ΔTCI/ΔCOM (Eq. 8-2a) | C11: =C7/C8
B12: PBPref = 0.85/(mar+0.85/N) (Eq. 8-2c) | C12: =0.85/(C9+0.85/C10)
B13: Decision | C13: =IF(AND(C11<=C12,C11<=5),"ACCEPT",IF(C11<=C12*1.05,"BORDERLINE - REJECT","REJECT"))
B14: Expected result: PBP=4.89 yr vs PBPref=4.81 yr → borderline reject. If this cell doesn't show that, a formula above is broken.
B16: Table 8-1 — mar by Risk Level (Peters & Timmerhaus) — reference for Sheet 1's mar input
B17: Risk level | C17: mar min | D17: mar max
B18: Safe - cost of capital | C18: 0.04 | D18: 0.08
B19: Low - new capacity / established market | C19: 0.08 | D19: 0.16
B20: Medium - new product/established market or new process tech | C20: 0.16 | D20: 0.24
B21: High - new product/process / new application | C21: 0.24 | D21: 0.32
B22: Very High - all-new / high R&D and marketing | C22: 0.32 | D22: 0.48
B24: Stage-Count Sweep — one row per N, every cost constituent visible (what stage cost what)
B25: Compressor selection is re-done for each N, not fixed at Sheet 1's choice: adiabatic head drops non-linearly as stages are added (Compressor Sizing.pptx slide 4), so a different N can genuinely land in a different Fig. 10-64 box. "Suggested Type" below recomputes the box match per row, the same way Sheet 2 does for a single N. Within one fixed N (Sheets 2-5), all individual stages share the same head under the equal-split/full-intercool assumption, so type does not differ stage-to-stage there — it's only across different N choices, here, that it can.
B27: N | C27: r_stage | D27: H_ad (ft) | E27: Suggested Type(s) | F27: Tout (°F) | G27: Temp Flag | H27: Train Power = Pc (hp) | I27: Compressor Cb @CE567 ($) | J27: Compressor Cp ($) | K27: Compressor BMC ($) | L27: Coolers (qty) | M27: Cooling Duty/unit (Btu/hr) | N27: Design Pressure (psig) | O27: LMTD (°F) | P27: HX Area/unit (ft²) | Q27: HX Cb @CE567 ($) | R27: HX Cp/unit ($) | S27: HX BMC/unit ($) | T27: HX BMC Total ($) | U27: Total Bare Module ($) | V27: Contingency 18% ($) | W27: Fee 3% ($) | X27: Total Module Cost ($) | Y27: Working Capital 15% ($) | Z27: TOTAL INSTALLED COST ($) | AA27: Incr. Capex ($) | AB27: Pretax Savings ($/yr) | AC27: After-Tax Cash Flow ($/yr) | AD27: Incr. PBP vs N-1 | AE27: Passes Econ?
B28: 1 | C28: ='1. Inputs'!$C$75^(1/B28) | D28: =('1. Inputs'!$C$7/('1. Inputs'!$C$7-1))*'1. Inputs'!$C$74*'1. Inputs'!$C$73*(C28^(('1. Inputs'!$C$7-1)/'1. Inputs'!$C$7)-1) | E28: =IF(LEN(AG28)=0,"(no match)",LEFT(AG28,LEN(AG28)-2)) | F28: ='1. Inputs'!$C$73*C28^(((1/(1-(('1. Inputs'!$C$7-1)/('1. Inputs'!$C$7*'3. Efficiency'!$C$80))))-1)/(1/(1-(('1. Inputs'!$C$7-1)/('1. Inputs'!$C$7*'3. Efficiency'!$C$80)))))-459.67 | G28: =IF(B28>999,"",IF(IF(LEN(AG28)=0,"None",LEFT(AG28,SEARCH(", ",AG28)-1))="None","UNKNOWN TYPE - no compressor in the coverage table fits these conditions; cannot verify Tallow, treated as EXCEEDS until inspected manually",IF(ISNUMBER(SEARCH("Reciprocating",IF(LEN(AG28)=0,"None",LEFT(AG28,SEARCH(", ",AG28)-1)))),IF(F28>350,"EXCEEDS 350F - add a stage",IF(F28>300,"CAUTION: 300-350F is vendor/lubricant dependent - inspect the specific compressor rating (outside scope of this spreadsheet)","OK")),IF(ISNUMBER(SEARCH("Centrifugal",IF(LEN(AG28)=0,"None",LEFT(AG28,SEARCH(", ",AG28)-1)))),IF(F28>446,"EXCEEDS 446F - add a stage",IF(F28>392,"CAUTION: 392-446F is vendor/lubricant dependent - inspect the specific compressor rating (outside scope of this spreadsheet)","OK")),IF(ISNUMBER(SEARCH("Rotary",IF(LEN(AG28)=0,"None",LEFT(AG28,SEARCH(", ",AG28)-1)))),IF(F28>350,"EXCEEDS 350F - add a stage",IF(F28>212,"CAUTION: 212-350F is vendor/lubricant dependent - inspect the specific compressor rating (outside scope of this spreadsheet)","OK")),"n/a (Axial/Fan - no Tallow range given in the deck)"))))) | H28: =B28*'1. Inputs'!$C$14*(((1/(1-(('1. Inputs'!$C$7-1)/('1. Inputs'!$C$7*'3. Efficiency'!$C$80))))/((1/(1-(('1. Inputs'!$C$7-1)/('1. Inputs'!$C$7*'3. Efficiency'!$C$80))))-1))*'1. Inputs'!$C$8*'1. Inputs'!$C$74*'1. Inputs'!$C$73*(C28^((((1/(1-(('1. Inputs'!$C$7-1)/('1. Inputs'!$C$7*'3. Efficiency'!$C$80)))))-1)/((1/(1-(('1. Inputs'!$C$7-1)/('1. Inputs'!$C$7*'3. Efficiency'!$C$80))))))-1))/'3. Efficiency'!$C$80/1980000 | I28: =IF(ISNUMBER(SEARCH("Centrifugal",IF(LEN(AG28)=0,"None",LEFT(AG28,SEARCH(", ",AG28)-1)))),EXP(9.1553+0.63*LN(H28)),IF(ISNUMBER(SEARCH("Reciprocating",IF(LEN(AG28)=0,"None",LEFT(AG28,SEARCH(", ",AG28)-1)))),EXP(4.6762+1.23*LN(H28)),IF(ISNUMBER(SEARCH("Screw",IF(LEN(AG28)=0,"None",LEFT(AG28,SEARCH(", ",AG28)-1)))),EXP(8.2496+0.7243*LN(H28)),"n/a - outside Seider Ch.16.5 correlation coverage"))) | J28: =IF(ISNUMBER(I28),I28*(IF('1. Inputs'!$C$58="Electric Motor",1,IF('1. Inputs'!$C$58="Steam Turbine",1.15,1.25)))*(IF('1. Inputs'!$C$59="Carbon Steel",1,IF('1. Inputs'!$C$59="Stainless Steel",2.5,5)))*('1. Inputs'!$C$57/567),"n/a - outside Seider correlation") | K28: =IF(ISNUMBER(J28),J28*'1. Inputs'!$C$60,"n/a") | L28: =MAX(B28-1,0) | M28: ='1. Inputs'!$C$14*(('1. Inputs'!$C$7/('1. Inputs'!$C$7-1))*'1. Inputs'!$C$74/778.169)*((F28+459.67)-'1. Inputs'!$C$73) | N28: ='1. Inputs'!$C$12*C28-14.696 | O28: =IF((F28-'1. Inputs'!$C$67)=('1. Inputs'!$C$11-'1. Inputs'!$C$66),(F28-'1. Inputs'!$C$67),((F28-'1. Inputs'!$C$67)-('1. Inputs'!$C$11-'1. Inputs'!$C$66))/LN((F28-'1. Inputs'!$C$67)/('1. Inputs'!$C$11-'1. Inputs'!$C$66))) | P28: =IF(O28<=0,"n/a - LMTD<=0, check cooling water temps",M28/('1. Inputs'!$C$65*O28)) | Q28: =IF(ISNUMBER(P28),IF('1. Inputs'!$C$62="Floating Head",EXP(12.0310-0.8709*LN(P28)+0.09005*LN(P28)^2),IF('1. Inputs'!$C$62="Fixed Head",EXP(11.4185-0.9228*LN(P28)+0.09861*LN(P28)^2),IF('1. Inputs'!$C$62="U-Tube",EXP(11.5510-0.9186*LN(P28)+0.09790*LN(P28)^2),EXP(12.3310-0.8709*LN(P28)+0.09005*LN(P28)^2)))),"n/a") | R28: =IF(ISNUMBER(Q28),Q28*(0.9803+0.018*(N28/100)+0.0017*(N28/100)^2)*((IF('1. Inputs'!$C$63="Carbon steel/Carbon steel",0,IF('1. Inputs'!$C$63="Carbon steel/Stainless steel",1.75,2.70)))+(P28/100)^(IF('1. Inputs'!$C$63="Carbon steel/Carbon steel",0,IF('1. Inputs'!$C$63="Carbon steel/Stainless steel",0.13,0.07))))*(IF('1. Inputs'!$C$64=8,1.25,IF('1. Inputs'!$C$64=12,1.12,IF('1. Inputs'!$C$64=16,1.05,1))))*('1. Inputs'!$C$57/567),"n/a") | S28: =IF(ISNUMBER(R28),R28*'1. Inputs'!$C$68,"n/a") | T28: =IF(ISNUMBER(S28),L28*S28,"n/a") | U28: =IF(AND(ISNUMBER(K28),ISNUMBER(T28)),K28+T28,"n/a - unsupported type for Seider costing") | V28: =IF(ISNUMBER(U28),0.18*U28,"n/a") | W28: =IF(ISNUMBER(U28),0.03*U28,"n/a") | X28: =IF(AND(ISNUMBER(U28),ISNUMBER(V28),ISNUMBER(W28)),U28+V28+W28,"n/a") | Y28: =IF(ISNUMBER(X28),0.15*X28,"n/a") | Z28: =IF(AND(ISNUMBER(X28),ISNUMBER(Y28)),X28+Y28,"n/a") | AA28: n/a (baseline) | AB28: n/a (baseline) | AC28: n/a (baseline) | AD28: n/a (baseline) | AE28: TRUE (baseline) | AG28: =IF(AND('1. Inputs'!$C$78>='2. Type Selection'!C14,'1. Inputs'!$C$78<='2. Type Selection'!D14,D28>='2. Type Selection'!E14,D28<='2. Type Selection'!F14),'2. Type Selection'!B14&", ","")&IF(AND('1. Inputs'!$C$78>='2. Type Selection'!C15,'1. Inputs'!$C$78<='2. Type Selection'!D15,D28>='2. Type Selection'!E15,D28<='2. Type Selection'!F15),'2. Type Selection'!B15&", ","")&IF(AND('1. Inputs'!$C$78>='2. Type Selection'!C16,'1. Inputs'!$C$78<='2. Type Selection'!D16,D28>='2. Type Selection'!E16,D28<='2. Type Selection'!F16),'2. Type Selection'!B16&", ","")&IF(AND('1. Inputs'!$C$78>='2. Type Selection'!C17,'1. Inputs'!$C$78<='2. Type Selection'!D17,D28>='2. Type Selection'!E17,D28<='2. Type Selection'!F17),'2. Type Selection'!B17&", ","")&IF(AND('1. Inputs'!$C$78>='2. Type Selection'!C18,'1. Inputs'!$C$78<='2. Type Selection'!D18,D28>='2. Type Selection'!E18,D28<='2. Type Selection'!F18),'2. Type Selection'!B18&", ","")&IF(AND('1. Inputs'!$C$78>='2. Type Selection'!C19,'1. Inputs'!$C$78<='2. Type Selection'!D19,D28>='2. Type Selection'!E19,D28<='2. Type Selection'!F19),'2. Type Selection'!B19&", ","")&IF(AND('1. Inputs'!$C$78>='2. Type Selection'!C20,'1. Inputs'!$C$78<='2. Type Selection'!D20,D28>='2. Type Selection'!E20,D28<='2. Type Selection'!F20),'2. Type Selection'!B20&", ","")&IF(AND('1. Inputs'!$C$78>='2. Type Selection'!C21,'1. Inputs'!$C$78<='2. Type Selection'!D21,D28>='2. Type Selection'!E21,D28<='2. Type Selection'!F21),'2. Type Selection'!B21&", ","")&IF(AND('1. Inputs'!$C$78>='2. Type Selection'!C22,'1. Inputs'!$C$78<='2. Type Selection'!D22,D28>='2. Type Selection'!E22,D28<='2. Type Selection'!F22),'2. Type Selection'!B22&", ","")&IF(AND('1. Inputs'!$C$78>='2. Type Selection'!C23,'1. Inputs'!$C$78<='2. Type Selection'!D23,D28>='2. Type Selection'!E23,D28<='2. Type Selection'!F23),'2. Type Selection'!B23&", ","")
B29: 2 | C29: ='1. Inputs'!$C$75^(1/B29) | D29: =('1. Inputs'!$C$7/('1. Inputs'!$C$7-1))*'1. Inputs'!$C$74*'1. Inputs'!$C$73*(C29^(('1. Inputs'!$C$7-1)/'1. Inputs'!$C$7)-1) | E29: =IF(LEN(AG29)=0,"(no match)",LEFT(AG29,LEN(AG29)-2)) | F29: ='1. Inputs'!$C$73*C29^(((1/(1-(('1. Inputs'!$C$7-1)/('1. Inputs'!$C$7*'3. Efficiency'!$C$80))))-1)/(1/(1-(('1. Inputs'!$C$7-1)/('1. Inputs'!$C$7*'3. Efficiency'!$C$80)))))-459.67 | G29: =IF(B29>999,"",IF(IF(LEN(AG29)=0,"None",LEFT(AG29,SEARCH(", ",AG29)-1))="None","UNKNOWN TYPE - no compressor in the coverage table fits these conditions; cannot verify Tallow, treated as EXCEEDS until inspected manually",IF(ISNUMBER(SEARCH("Reciprocating",IF(LEN(AG29)=0,"None",LEFT(AG29,SEARCH(", ",AG29)-1)))),IF(F29>350,"EXCEEDS 350F - add a stage",IF(F29>300,"CAUTION: 300-350F is vendor/lubricant dependent - inspect the specific compressor rating (outside scope of this spreadsheet)","OK")),IF(ISNUMBER(SEARCH("Centrifugal",IF(LEN(AG29)=0,"None",LEFT(AG29,SEARCH(", ",AG29)-1)))),IF(F29>446,"EXCEEDS 446F - add a stage",IF(F29>392,"CAUTION: 392-446F is vendor/lubricant dependent - inspect the specific compressor rating (outside scope of this spreadsheet)","OK")),IF(ISNUMBER(SEARCH("Rotary",IF(LEN(AG29)=0,"None",LEFT(AG29,SEARCH(", ",AG29)-1)))),IF(F29>350,"EXCEEDS 350F - add a stage",IF(F29>212,"CAUTION: 212-350F is vendor/lubricant dependent - inspect the specific compressor rating (outside scope of this spreadsheet)","OK")),"n/a (Axial/Fan - no Tallow range given in the deck)"))))) | H29: =B29*'1. Inputs'!$C$14*(((1/(1-(('1. Inputs'!$C$7-1)/('1. Inputs'!$C$7*'3. Efficiency'!$C$80))))/((1/(1-(('1. Inputs'!$C$7-1)/('1. Inputs'!$C$7*'3. Efficiency'!$C$80))))-1))*'1. Inputs'!$C$8*'1. Inputs'!$C$74*'1. Inputs'!$C$73*(C29^((((1/(1-(('1. Inputs'!$C$7-1)/('1. Inputs'!$C$7*'3. Efficiency'!$C$80)))))-1)/((1/(1-(('1. Inputs'!$C$7-1)/('1. Inputs'!$C$7*'3. Efficiency'!$C$80))))))-1))/'3. Efficiency'!$C$80/1980000 | I29: =IF(ISNUMBER(SEARCH("Centrifugal",IF(LEN(AG29)=0,"None",LEFT(AG29,SEARCH(", ",AG29)-1)))),EXP(9.1553+0.63*LN(H29)),IF(ISNUMBER(SEARCH("Reciprocating",IF(LEN(AG29)=0,"None",LEFT(AG29,SEARCH(", ",AG29)-1)))),EXP(4.6762+1.23*LN(H29)),IF(ISNUMBER(SEARCH("Screw",IF(LEN(AG29)=0,"None",LEFT(AG29,SEARCH(", ",AG29)-1)))),EXP(8.2496+0.7243*LN(H29)),"n/a - outside Seider Ch.16.5 correlation coverage"))) | J29: =IF(ISNUMBER(I29),I29*(IF('1. Inputs'!$C$58="Electric Motor",1,IF('1. Inputs'!$C$58="Steam Turbine",1.15,1.25)))*(IF('1. Inputs'!$C$59="Carbon Steel",1,IF('1. Inputs'!$C$59="Stainless Steel",2.5,5)))*('1. Inputs'!$C$57/567),"n/a - outside Seider correlation") | K29: =IF(ISNUMBER(J29),J29*'1. Inputs'!$C$60,"n/a") | L29: =MAX(B29-1,0) | M29: ='1. Inputs'!$C$14*(('1. Inputs'!$C$7/('1. Inputs'!$C$7-1))*'1. Inputs'!$C$74/778.169)*((F29+459.67)-'1. Inputs'!$C$73) | N29: ='1. Inputs'!$C$12*C29-14.696 | O29: =IF((F29-'1. Inputs'!$C$67)=('1. Inputs'!$C$11-'1. Inputs'!$C$66),(F29-'1. Inputs'!$C$67),((F29-'1. Inputs'!$C$67)-('1. Inputs'!$C$11-'1. Inputs'!$C$66))/LN((F29-'1. Inputs'!$C$67)/('1. Inputs'!$C$11-'1. Inputs'!$C$66))) | P29: =IF(O29<=0,"n/a - LMTD<=0, check cooling water temps",M29/('1. Inputs'!$C$65*O29)) | Q29: =IF(ISNUMBER(P29),IF('1. Inputs'!$C$62="Floating Head",EXP(12.0310-0.8709*LN(P29)+0.09005*LN(P29)^2),IF('1. Inputs'!$C$62="Fixed Head",EXP(11.4185-0.9228*LN(P29)+0.09861*LN(P29)^2),IF('1. Inputs'!$C$62="U-Tube",EXP(11.5510-0.9186*LN(P29)+0.09790*LN(P29)^2),EXP(12.3310-0.8709*LN(P29)+0.09005*LN(P29)^2)))),"n/a") | R29: =IF(ISNUMBER(Q29),Q29*(0.9803+0.018*(N29/100)+0.0017*(N29/100)^2)*((IF('1. Inputs'!$C$63="Carbon steel/Carbon steel",0,IF('1. Inputs'!$C$63="Carbon steel/Stainless steel",1.75,2.70)))+(P29/100)^(IF('1. Inputs'!$C$63="Carbon steel/Carbon steel",0,IF('1. Inputs'!$C$63="Carbon steel/Stainless steel",0.13,0.07))))*(IF('1. Inputs'!$C$64=8,1.25,IF('1. Inputs'!$C$64=12,1.12,IF('1. Inputs'!$C$64=16,1.05,1))))*('1. Inputs'!$C$57/567),"n/a") | S29: =IF(ISNUMBER(R29),R29*'1. Inputs'!$C$68,"n/a") | T29: =IF(ISNUMBER(S29),L29*S29,"n/a") | U29: =IF(AND(ISNUMBER(K29),ISNUMBER(T29)),K29+T29,"n/a - unsupported type for Seider costing") | V29: =IF(ISNUMBER(U29),0.18*U29,"n/a") | W29: =IF(ISNUMBER(U29),0.03*U29,"n/a") | X29: =IF(AND(ISNUMBER(U29),ISNUMBER(V29),ISNUMBER(W29)),U29+V29+W29,"n/a") | Y29: =IF(ISNUMBER(X29),0.15*X29,"n/a") | Z29: =IF(AND(ISNUMBER(X29),ISNUMBER(Y29)),X29+Y29,"n/a") | AA29: =IF(AND(ISNUMBER(Z29),ISNUMBER(Z28)),Z29-Z28,"n/a") | AB29: =(H28-H29)*0.7457*'1. Inputs'!$C$18*'1. Inputs'!$C$19 | AC29: =IF(ISNUMBER(AA29),(1-'1. Inputs'!$C$70)*AB29+AA29/'1. Inputs'!$C$22,"n/a") | AD29: =IF(NOT(ISNUMBER(AA29)),"n/a",IF(AA29<=0,"FREE - cheaper capital AND lower operating cost",IF(OR(NOT(ISNUMBER(AC29)),AC29<=0),"n/a",AA29/AC29))) | AE29: =IF(OR(AD29="n/a"),FALSE,IF(AD29="FREE - cheaper capital AND lower operating cost",TRUE,IF(AND(ISNUMBER(AD29),AD29<=0.85/('1. Inputs'!$C$21+0.85/'1. Inputs'!$C$22),AD29<=5),TRUE,FALSE))) | AG29: =IF(AND('1. Inputs'!$C$78>='2. Type Selection'!C14,'1. Inputs'!$C$78<='2. Type Selection'!D14,D29>='2. Type Selection'!E14,D29<='2. Type Selection'!F14),'2. Type Selection'!B14&", ","")&IF(AND('1. Inputs'!$C$78>='2. Type Selection'!C15,'1. Inputs'!$C$78<='2. Type Selection'!D15,D29>='2. Type Selection'!E15,D29<='2. Type Selection'!F15),'2. Type Selection'!B15&", ","")&IF(AND('1. Inputs'!$C$78>='2. Type Selection'!C16,'1. Inputs'!$C$78<='2. Type Selection'!D16,D29>='2. Type Selection'!E16,D29<='2. Type Selection'!F16),'2. Type Selection'!B16&", ","")&IF(AND('1. Inputs'!$C$78>='2. Type Selection'!C17,'1. Inputs'!$C$78<='2. Type Selection'!D17,D29>='2. Type Selection'!E17,D29<='2. Type Selection'!F17),'2. Type Selection'!B17&", ","")&IF(AND('1. Inputs'!$C$78>='2. Type Selection'!C18,'1. Inputs'!$C$78<='2. Type Selection'!D18,D29>='2. Type Selection'!E18,D29<='2. Type Selection'!F18),'2. Type Selection'!B18&", ","")&IF(AND('1. Inputs'!$C$78>='2. Type Selection'!C19,'1. Inputs'!$C$78<='2. Type Selection'!D19,D29>='2. Type Selection'!E19,D29<='2. Type Selection'!F19),'2. Type Selection'!B19&", ","")&IF(AND('1. Inputs'!$C$78>='2. Type Selection'!C20,'1. Inputs'!$C$78<='2. Type Selection'!D20,D29>='2. Type Selection'!E20,D29<='2. Type Selection'!F20),'2. Type Selection'!B20&", ","")&IF(AND('1. Inputs'!$C$78>='2. Type Selection'!C21,'1. Inputs'!$C$78<='2. Type Selection'!D21,D29>='2. Type Selection'!E21,D29<='2. Type Selection'!F21),'2. Type Selection'!B21&", ","")&IF(AND('1. Inputs'!$C$78>='2. Type Selection'!C22,'1. Inputs'!$C$78<='2. Type Selection'!D22,D29>='2. Type Selection'!E22,D29<='2. Type Selection'!F22),'2. Type Selection'!B22&", ","")&IF(AND('1. Inputs'!$C$78>='2. Type Selection'!C23,'1. Inputs'!$C$78<='2. Type Selection'!D23,D29>='2. Type Selection'!E23,D29<='2. Type Selection'!F23),'2. Type Selection'!B23&", ","")
